============================================================== test session starts ==============================================================
platform linux -- Python 3.8.10, pytest-7.4.3, pluggy-1.3.0 -- /usr/bin/python3
rootdir: /home/jose/Dev/django_sprint3
configfile: pytest.ini
testpaths: tests/
collected 50 items / 8 errors                                                                                                                   

==================================================================== ERRORS =====================================================================
_________________________________________________ ERROR collecting tests/test_category_model.py _________________________________________________
../../.local/lib/python3.8/site-packages/_pytest/runner.py:341: in from_call
    result: Optional[TResult] = func()
../../.local/lib/python3.8/site-packages/_pytest/runner.py:372: in <lambda>
    call = CallInfo.from_call(lambda: list(collector.collect()), "collect")
../../.local/lib/python3.8/site-packages/_pytest/python.py:531: in collect
    self._inject_setup_module_fixture()
../../.local/lib/python3.8/site-packages/_pytest/python.py:545: in _inject_setup_module_fixture
    self.obj, ("setUpModule", "setup_module")
../../.local/lib/python3.8/site-packages/_pytest/python.py:310: in obj
    self._obj = obj = self._getobj()
../../.local/lib/python3.8/site-packages/_pytest/python.py:528: in _getobj
    return self._importtestmodule()
../../.local/lib/python3.8/site-packages/_pytest/python.py:617: in _importtestmodule
    mod = import_path(self.path, mode=importmode, root=self.config.rootpath)
../../.local/lib/python3.8/site-packages/_pytest/pathlib.py:567: in import_path
    importlib.import_module(module_name)
/usr/lib/python3.8/importlib/__init__.py:127: in import_module
    return _bootstrap._gcd_import(name[level:], package, level)
<frozen importlib._bootstrap>:1014: in _gcd_import
    ???
<frozen importlib._bootstrap>:991: in _find_and_load
    ???
<frozen importlib._bootstrap>:975: in _find_and_load_unlocked
    ???
<frozen importlib._bootstrap>:671: in _load_unlocked
    ???
../../.local/lib/python3.8/site-packages/_pytest/assertion/rewrite.py:186: in exec_module
    exec(co, module.__dict__)
tests/test_category_model.py:5: in <module>
    from blog.models import Category
blogicum/blog/models.py:4: in <module>
    User = get_user_model()
../../.local/lib/python3.8/site-packages/django/contrib/auth/__init__.py:170: in get_user_model
    return django_apps.get_model(settings.AUTH_USER_MODEL, require_ready=False)
../../.local/lib/python3.8/site-packages/django/conf/__init__.py:102: in __getattr__
    self._setup(name)
../../.local/lib/python3.8/site-packages/django/conf/__init__.py:82: in _setup
    raise ImproperlyConfigured(
E   django.core.exceptions.ImproperlyConfigured: Requested setting AUTH_USER_MODEL, but settings are not configured. You must either define the environment variable DJANGO_SETTINGS_MODULE or call settings.configure() before accessing settings.
______________________________________________________ ERROR collecting tests/test_html.py ______________________________________________________
ImportError while importing test module '/home/jose/Dev/django_sprint3/tests/test_html.py'.
Hint: make sure your test modules/packages have valid Python names.
Traceback:
../../.local/lib/python3.8/site-packages/_pytest/python.py:617: in _importtestmodule
    mod = import_path(self.path, mode=importmode, root=self.config.rootpath)
../../.local/lib/python3.8/site-packages/_pytest/pathlib.py:567: in import_path
    importlib.import_module(module_name)
/usr/lib/python3.8/importlib/__init__.py:127: in import_module
    return _bootstrap._gcd_import(name[level:], package, level)
<frozen importlib._bootstrap>:1014: in _gcd_import
    ???
<frozen importlib._bootstrap>:991: in _find_and_load
    ???
<frozen importlib._bootstrap>:975: in _find_and_load_unlocked
    ???
<frozen importlib._bootstrap>:671: in _load_unlocked
    ???
../../.local/lib/python3.8/site-packages/_pytest/assertion/rewrite.py:186: in exec_module
    exec(co, module.__dict__)
../django_sprint1/tests/test_html.py:3: in <module>
    from tests.conftest import try_get_url
E   ModuleNotFoundError: No module named 'tests'
_________________________________________________ ERROR collecting tests/test_location_model.py _________________________________________________
../../.local/lib/python3.8/site-packages/_pytest/runner.py:341: in from_call
    result: Optional[TResult] = func()
../../.local/lib/python3.8/site-packages/_pytest/runner.py:372: in <lambda>
    call = CallInfo.from_call(lambda: list(collector.collect()), "collect")
../../.local/lib/python3.8/site-packages/_pytest/python.py:531: in collect
    self._inject_setup_module_fixture()
../../.local/lib/python3.8/site-packages/_pytest/python.py:545: in _inject_setup_module_fixture
    self.obj, ("setUpModule", "setup_module")
../../.local/lib/python3.8/site-packages/_pytest/python.py:310: in obj
    self._obj = obj = self._getobj()
../../.local/lib/python3.8/site-packages/_pytest/python.py:528: in _getobj
    return self._importtestmodule()
../../.local/lib/python3.8/site-packages/_pytest/python.py:617: in _importtestmodule
    mod = import_path(self.path, mode=importmode, root=self.config.rootpath)
../../.local/lib/python3.8/site-packages/_pytest/pathlib.py:567: in import_path
    importlib.import_module(module_name)
/usr/lib/python3.8/importlib/__init__.py:127: in import_module
    return _bootstrap._gcd_import(name[level:], package, level)
<frozen importlib._bootstrap>:1014: in _gcd_import
    ???
<frozen importlib._bootstrap>:991: in _find_and_load
    ???
<frozen importlib._bootstrap>:975: in _find_and_load_unlocked
    ???
<frozen importlib._bootstrap>:671: in _load_unlocked
    ???
../../.local/lib/python3.8/site-packages/_pytest/assertion/rewrite.py:186: in exec_module
    exec(co, module.__dict__)
tests/test_location_model.py:4: in <module>
    from blog.models import Location
blogicum/blog/models.py:4: in <module>
    User = get_user_model()
../../.local/lib/python3.8/site-packages/django/contrib/auth/__init__.py:170: in get_user_model
    return django_apps.get_model(settings.AUTH_USER_MODEL, require_ready=False)
../../.local/lib/python3.8/site-packages/django/conf/__init__.py:102: in __getattr__
    self._setup(name)
../../.local/lib/python3.8/site-packages/django/conf/__init__.py:82: in _setup
    raise ImproperlyConfigured(
E   django.core.exceptions.ImproperlyConfigured: Requested setting AUTH_USER_MODEL, but settings are not configured. You must either define the environment variable DJANGO_SETTINGS_MODULE or call settings.configure() before accessing settings.
_________________________________________________ ERROR collecting tests/test_pageapp_views.py __________________________________________________
ImportError while importing test module '/home/jose/Dev/django_sprint3/tests/test_pageapp_views.py'.
Hint: make sure your test modules/packages have valid Python names.
Traceback:
../../.local/lib/python3.8/site-packages/_pytest/python.py:617: in _importtestmodule
    mod = import_path(self.path, mode=importmode, root=self.config.rootpath)
../../.local/lib/python3.8/site-packages/_pytest/pathlib.py:567: in import_path
    importlib.import_module(module_name)
/usr/lib/python3.8/importlib/__init__.py:127: in import_module
    return _bootstrap._gcd_import(name[level:], package, level)
<frozen importlib._bootstrap>:1014: in _gcd_import
    ???
<frozen importlib._bootstrap>:991: in _find_and_load
    ???
<frozen importlib._bootstrap>:975: in _find_and_load_unlocked
    ???
<frozen importlib._bootstrap>:671: in _load_unlocked
    ???
../../.local/lib/python3.8/site-packages/_pytest/assertion/rewrite.py:186: in exec_module
    exec(co, module.__dict__)
tests/test_pageapp_views.py:4: in <module>
    from pytest_django.asserts import assertTemplateUsed
E   ModuleNotFoundError: No module named 'pytest_django'
_______________________________________________ ERROR collecting tests/test_post_detail_views.py ________________________________________________
../../.local/lib/python3.8/site-packages/_pytest/runner.py:341: in from_call
    result: Optional[TResult] = func()
../../.local/lib/python3.8/site-packages/_pytest/runner.py:372: in <lambda>
    call = CallInfo.from_call(lambda: list(collector.collect()), "collect")
../../.local/lib/python3.8/site-packages/_pytest/python.py:531: in collect
    self._inject_setup_module_fixture()
../../.local/lib/python3.8/site-packages/_pytest/python.py:545: in _inject_setup_module_fixture
    self.obj, ("setUpModule", "setup_module")
../../.local/lib/python3.8/site-packages/_pytest/python.py:310: in obj
    self._obj = obj = self._getobj()
../../.local/lib/python3.8/site-packages/_pytest/python.py:528: in _getobj
    return self._importtestmodule()
../../.local/lib/python3.8/site-packages/_pytest/python.py:617: in _importtestmodule
    mod = import_path(self.path, mode=importmode, root=self.config.rootpath)
../../.local/lib/python3.8/site-packages/_pytest/pathlib.py:567: in import_path
    importlib.import_module(module_name)
/usr/lib/python3.8/importlib/__init__.py:127: in import_module
    return _bootstrap._gcd_import(name[level:], package, level)
<frozen importlib._bootstrap>:1014: in _gcd_import
    ???
<frozen importlib._bootstrap>:991: in _find_and_load
    ???
<frozen importlib._bootstrap>:975: in _find_and_load_unlocked
    ???
<frozen importlib._bootstrap>:671: in _load_unlocked
    ???
../../.local/lib/python3.8/site-packages/_pytest/assertion/rewrite.py:186: in exec_module
    exec(co, module.__dict__)
tests/test_post_detail_views.py:5: in <module>
    from blog.models import Post
blogicum/blog/models.py:4: in <module>
    User = get_user_model()
../../.local/lib/python3.8/site-packages/django/contrib/auth/__init__.py:170: in get_user_model
    return django_apps.get_model(settings.AUTH_USER_MODEL, require_ready=False)
../../.local/lib/python3.8/site-packages/django/conf/__init__.py:102: in __getattr__
    self._setup(name)
../../.local/lib/python3.8/site-packages/django/conf/__init__.py:82: in _setup
    raise ImproperlyConfigured(
E   django.core.exceptions.ImproperlyConfigured: Requested setting AUTH_USER_MODEL, but settings are not configured. You must either define the environment variable DJANGO_SETTINGS_MODULE or call settings.configure() before accessing settings.
___________________________________________________ ERROR collecting tests/test_post_model.py ___________________________________________________
../../.local/lib/python3.8/site-packages/_pytest/runner.py:341: in from_call
    result: Optional[TResult] = func()
../../.local/lib/python3.8/site-packages/_pytest/runner.py:372: in <lambda>
    call = CallInfo.from_call(lambda: list(collector.collect()), "collect")
../../.local/lib/python3.8/site-packages/_pytest/python.py:531: in collect
    self._inject_setup_module_fixture()
../../.local/lib/python3.8/site-packages/_pytest/python.py:545: in _inject_setup_module_fixture
    self.obj, ("setUpModule", "setup_module")
../../.local/lib/python3.8/site-packages/_pytest/python.py:310: in obj
    self._obj = obj = self._getobj()
../../.local/lib/python3.8/site-packages/_pytest/python.py:528: in _getobj
    return self._importtestmodule()
../../.local/lib/python3.8/site-packages/_pytest/python.py:617: in _importtestmodule
    mod = import_path(self.path, mode=importmode, root=self.config.rootpath)
../../.local/lib/python3.8/site-packages/_pytest/pathlib.py:567: in import_path
    importlib.import_module(module_name)
/usr/lib/python3.8/importlib/__init__.py:127: in import_module
    return _bootstrap._gcd_import(name[level:], package, level)
<frozen importlib._bootstrap>:1014: in _gcd_import
    ???
<frozen importlib._bootstrap>:991: in _find_and_load
    ???
<frozen importlib._bootstrap>:975: in _find_and_load_unlocked
    ???
<frozen importlib._bootstrap>:671: in _load_unlocked
    ???
../../.local/lib/python3.8/site-packages/_pytest/assertion/rewrite.py:186: in exec_module
    exec(co, module.__dict__)
tests/test_post_model.py:6: in <module>
    from blog.models import Post
blogicum/blog/models.py:4: in <module>
    User = get_user_model()
../../.local/lib/python3.8/site-packages/django/contrib/auth/__init__.py:170: in get_user_model
    return django_apps.get_model(settings.AUTH_USER_MODEL, require_ready=False)
../../.local/lib/python3.8/site-packages/django/conf/__init__.py:102: in __getattr__
    self._setup(name)
../../.local/lib/python3.8/site-packages/django/conf/__init__.py:82: in _setup
    raise ImproperlyConfigured(
E   django.core.exceptions.ImproperlyConfigured: Requested setting AUTH_USER_MODEL, but settings are not configured. You must either define the environment variable DJANGO_SETTINGS_MODULE or call settings.configure() before accessing settings.
________________________________________________ ERROR collecting tests/test_posts_page_views.py ________________________________________________
ImportError while importing test module '/home/jose/Dev/django_sprint3/tests/test_posts_page_views.py'.
Hint: make sure your test modules/packages have valid Python names.
Traceback:
../../.local/lib/python3.8/site-packages/_pytest/python.py:617: in _importtestmodule
    mod = import_path(self.path, mode=importmode, root=self.config.rootpath)
../../.local/lib/python3.8/site-packages/_pytest/pathlib.py:567: in import_path
    importlib.import_module(module_name)
/usr/lib/python3.8/importlib/__init__.py:127: in import_module
    return _bootstrap._gcd_import(name[level:], package, level)
<frozen importlib._bootstrap>:1014: in _gcd_import
    ???
<frozen importlib._bootstrap>:991: in _find_and_load
    ???
<frozen importlib._bootstrap>:975: in _find_and_load_unlocked
    ???
<frozen importlib._bootstrap>:671: in _load_unlocked
    ???
../../.local/lib/python3.8/site-packages/_pytest/assertion/rewrite.py:186: in exec_module
    exec(co, module.__dict__)
tests/test_posts_page_views.py:3: in <module>
    from tests.fixtures.fixture_data import N_TEST_POSTS, N_POSTS_LIMIT
E   ModuleNotFoundError: No module named 'tests'
___________________________________________________ ERROR collecting tests/test_templates.py ____________________________________________________
ImportError while importing test module '/home/jose/Dev/django_sprint3/tests/test_templates.py'.
Hint: make sure your test modules/packages have valid Python names.
Traceback:
../../.local/lib/python3.8/site-packages/_pytest/python.py:617: in _importtestmodule
    mod = import_path(self.path, mode=importmode, root=self.config.rootpath)
../../.local/lib/python3.8/site-packages/_pytest/pathlib.py:567: in import_path
    importlib.import_module(module_name)
/usr/lib/python3.8/importlib/__init__.py:127: in import_module
    return _bootstrap._gcd_import(name[level:], package, level)
<frozen importlib._bootstrap>:1014: in _gcd_import
    ???
<frozen importlib._bootstrap>:991: in _find_and_load
    ???
<frozen importlib._bootstrap>:975: in _find_and_load_unlocked
    ???
<frozen importlib._bootstrap>:671: in _load_unlocked
    ???
../../.local/lib/python3.8/site-packages/_pytest/assertion/rewrite.py:186: in exec_module
    exec(co, module.__dict__)
../django_sprint1/tests/test_templates.py:4: in <module>
    from pytest_django.asserts import assertTemplateUsed
E   ModuleNotFoundError: No module named 'pytest_django'
============================================================ short test summary info ============================================================
ERROR tests/test_category_model.py - django.core.exceptions.ImproperlyConfigured: Requested setting AUTH_USER_MODEL, but settings are not configured. You must either define the ...
ERROR tests/test_html.py
ERROR tests/test_location_model.py - django.core.exceptions.ImproperlyConfigured: Requested setting AUTH_USER_MODEL, but settings are not configured. You must either define the ...
ERROR tests/test_pageapp_views.py
ERROR tests/test_post_detail_views.py - django.core.exceptions.ImproperlyConfigured: Requested setting AUTH_USER_MODEL, but settings are not configured. You must either define the ...
ERROR tests/test_post_model.py - django.core.exceptions.ImproperlyConfigured: Requested setting AUTH_USER_MODEL, but settings are not configured. You must either define the ...
ERROR tests/test_posts_page_views.py
ERROR tests/test_templates.py
!!!!!!!!!!!!!!!!!!!!!!!!!!!!!!!!!!!!!!!!!!!!!!!!!!!! Interrupted: 8 errors during collection !!!!!!!!!!!!!!!!!!!!!!!!!!!!!!!!!!!!!!!!!!!!!!!!!!!!
========================================================= 2 warnings, 8 errors in 1.64s =========================================================
